Workbook

Sheet ملخص للعميل
A1: ملخص تكلفة أعمال الرخام – فيلا سكنية – الرياض
A2: شركة الرخام (المقاول) – حسب المستخلص المحدث بتاريخ 27/9/2026 – المبالغ بالريال السعودي
A3: البيان | B3: القيمة قبل الضريبة | C3: ضريبة القيمة المضافة 15% | D3: الإجمالي شامل الضريبة
A4: أولاً: الأعمال المنفذة (حسب الأدوار)
A5: الملحق العلوي | B5: ='مستخلص الشركة'!I11 | C5: =B5*'مستخلص الشركة'!$F$29 | D5: =B5+C5
A6: الدور الأول | B6: ='مستخلص الشركة'!I16 | C6: =B6*'مستخلص الشركة'!$F$29 | D6: =B6+C6
A7: القبو | B7: ='مستخلص الشركة'!I21 | C7: =B7*'مستخلص الشركة'!$F$29 | D7: =B7+C7
A8: الأدراج | B8: ='مستخلص الشركة'!I27 | C8: =B8*'مستخلص الشركة'!$F$29 | D8: =B8+C8
A9: إجمالي الأعمال المنفذة | B9: =SUM(B5:B8) | C9: =B9*'مستخلص الشركة'!$F$29 | D9: =B9+C9
A10: ثانياً: الدور الأرضي
A11: توريد رخام كالكتا إيطالي نخب أول 2 سم (1) – أرضيات ودرج وجدران مداخل المجالس | B11: ='أعمال الأرضي المتبقية'!G5 | C11: =B11*'مستخلص الشركة'!$F$29 | D11: =B11+C11
A12: توريد رخام كالكتا إيطالي نخب أول 2 سم (2) – أرضيات وجدران الحمامات | B12: ='أعمال الأرضي المتبقية'!G6 | C12: =B12*'مستخلص الشركة'!$F$29 | D12: =B12+C12
A13: قص وتركيب الدور الأرضي | B13: ='أعمال الأرضي المتبقية'!G12 | C13: =B13*'مستخلص الشركة'!$F$29 | D13: =B13+C13
A14: إجمالي الدور الأرضي | B14: =SUM(B11:B13) | C14: =B14*'مستخلص الشركة'!$F$29 | D14: =B14+C14
A15: إجمالي قيمة العقد (المشروع كامل) | B15: =B9+B14 | C15: =B15*'مستخلص الشركة'!$F$29 | D15: =B15+C15
A16: إجمالي المبالغ المحولة للشركة | D16: ='مستخلص الشركة'!I43
A17: المطلوب تحويله للشركة من العميل | D17: =D15-D16
A18: ملاحظات:
A19: • تم خصم 20 م² من الرخام المرتجع (المستخدم في درج الأول للعلوي) من قيمة الأدراج.
A20: ="• المبالغ المحولة تشمل 3 دفعات: "&TEXT('مستخلص الشركة'!I40,"#,##0")&" + "&TEXT('مستخلص الشركة'!I41,"#,##0")&" + "&TEXT('مستخلص الشركة'!I42,"#,##0")&" ر.س."
A21: • تكلفة الدور الأرضي حسب عرض توريد مورد الرخام بتاريخ 29/09/2026 وعرض قص وتركيب القص والتركيب بتاريخ 21/09/2026 (الدفع 100% مقدم).
A22: • لم تكن أمتار جدران الحمامات الزائدة محتسبة في العقد الأساسي (عرض السعر 1534/24).
A23: التوفير مقارنة بقيمة العقد الأصلي (عرض السعر)
A24: البيان | B24: القيمة قبل الضريبة | C24: ضريبة القيمة المضافة 15% | D24: الإجمالي شامل الضريبة
A25: قيمة العقد الأصلي حسب عرض السعر (1534/24) | B25: ='مستخلص الرخام'!H13 | C25: ='مستخلص الرخام'!H14 | D25: ='مستخلص الرخام'!H15
A26: الإجمالي الحالي للمشروع كامل | B26: =B15 | C26: =C15 | D26: =D15
A27: قيمة التوفير عن العقد | B27: =B25-B26 | C27: =C25-C26 | D27: =D25-D26
A28: نسبة التوفير من قيمة العقد | B28: =IF(B25=0,0,B27/B25) | C28: =IF(C25=0,0,C27/C25)
A29: رخام ارضيات و درج و جدران مداخل المجالس فى الدور الارضى | B29: رخام جدران و ارضيات الحمامات بالدور الارضي
A31: ملاحظات على الرخام

Sheet الملخص
A1: ملخص أعمال ومستخلص الرخام – فيلا سكنية – الرياض
A2: 1) قيمة التعاقد
A3: البيان | B3: حسب الشركة | C3: المعتمد / الصحيح | D3: الفرق | E3: ملاحظات
A4: قيمة التعاقد شامل الضريبة (عرض السعر 1534/24) | B4: ='مستخلص الرخام'!H15 | C4: ='مستخلص الرخام'!H15 | D4: =C4-B4
A6: 2) الأعمال المنفذة (قبل الضريبة)
A7: البيان | B7: حسب الشركة | C7: المعتمد / الصحيح | D7: الفرق | E7: ملاحظات
A8: الملحق العلوي | B8: ='مستخلص الشركة'!G11 | C8: ='مستخلص الشركة'!I11 | D8: =C8-B8
A9: الدور الأول | B9: ='مستخلص الشركة'!G16 | C9: ='مستخلص الشركة'!I16 | D9: =C9-B9
A10: القبو | B10: ='مستخلص الشركة'!G21 | C10: ='مستخلص الشركة'!I21 | D10: =C10-B10
A11: الأدراج | B11: ='مستخلص الشركة'!G27 | C11: ='مستخلص الشركة'!I27 | D11: =C11-B11
A12: إجمالي الأعمال قبل الضريبة | B12: =SUM(B8:B11) | C12: =SUM(C8:C11) | D12: =C12-B12
A13: ضريبة القيمة المضافة 15% | B13: ='مستخلص الشركة'!G29 | C13: ='مستخلص الشركة'!I29 | D13: =C13-B13
A14: إجمالي الأعمال شامل الضريبة | B14: =B12+B13 | C14: =C12+C13 | D14: =C14-B14
A16: 3) الدفعات المحولة للشركة
A17: البيان | B17: حسب الشركة | C17: المعتمد / الصحيح | D17: الفرق | E17: ملاحظات
A18: الدفعة الأولى 2025-12-09 | B18: ='مستخلص الشركة'!I40 | C18: ='مستخلص الشركة'!I40 | D18: =C18-B18
A19: الدفعة الثانية 2026-03-31 | B19: 0 | C19: ='مستخلص الشركة'!I41 | D19: =C19-B19 | E19: دفعة منسية في مستخلص الشركة
A20: الدفعة الثالثة 2026-05-03 | B20: ='مستخلص الشركة'!I42 | C20: ='مستخلص الشركة'!I42 | D20: =C20-B20
A21: إجمالي الدفعات | B21: =SUM(B18:B20) | C21: =SUM(C18:C20) | D21: =C21-B21
A23: 4) الموقف المالي
A24: البيان | B24: حسب الشركة | C24: المعتمد / الصحيح | D24: الفرق | E24: ملاحظات
A25: الرصيد لصالح المالك عند الشركة (المدفوع – الأعمال) | B25: =B21-B14 | C25: =C21-C14 | D25: =C25-B25 | E25: موجب = مبلغ مدفوع زيادة عن الأعمال المنفذة
A26: نسبة الأعمال المنفذة من قيمة التعاقد | B26: =B14/B4 | C26: =C14/C4
A27: نسبة المدفوع من قيمة التعاقد | B27: =B21/B4 | C27: =C21/C4
A28: المتبقي من قيمة التعاقد للسداد | B28: =B4-B21 | C28: =C4-C21 | D28: =C28-B28 | E28: يطابق كشف الحسابات
A29: الرصيد المتبقي عند الشركة حسب مستخلصهم | B29: =B25
A30: + الدفعة الثانية المنسية + خصم 20 م² رخام مكسور قابل للاستخدام | B30: =D25
A31: المتبقي عند شركة الرخام لصالح المالك | B31: =B29+B30 | D31: =IF(ROUND(B31-C25,2)=0,"يطابق الرصيد الصحيح بالموقف المالي","مراجعة")
A32: − توريد رخام الدور الأرضي (متبقي – شامل الضريبة) | B32: ='أعمال الأرضي المتبقية'!G7*(1+'أعمال الأرضي المتبقية'!F15)
A33: − قص وتركيب الدور الأرضي (متبقي – شامل الضريبة) | B33: ='أعمال الأرضي المتبقية'!G12*(1+'أعمال الأرضي المتبقية'!F15) | D33: عرض القص والتركيب – الدفع 100% مقدم
A34: الصافي بعد استكمال الدور الأرضي | B34: =B31-B32-B33 | D34: =IF(B34>=0,"لصالح المالك","مستحق لشركة الرخام")
A36: 5) ملاحظات للمتابعة مع الشركة
A37: • بند «أرضيات الملحق العلوي – مكرر» 70 م²: الرخام المرتجع للشركة (من المكسور ومن الكمية المكررة) تم استخدامه في 20 م² من درج الأول للعلوي، وتم خصمها في المستخلص المحدث 27/9/2026 (27.53 ← 7.53 م²).
A38: • النعلات (الملحق العلوي والدور الأول والقبو) والأدراج (من الأرضي للقبو ومن الأول للعلوي) لم يتم توريدها حتى تاريخه رغم احتسابها في مستخلص الشركة.
A40: 6) التكلفة الكاملة للمشروع – بنود تفصيلية
A41: البند | B41: القيمة قبل الضريبة | C41: ضريبة القيمة المضافة | D41: الإجمالي شامل الضريبة | E41: الكمية × سعر الوحدة
A42: أولاً: الأعمال المنفذة – شركة الرخام (حسب المستخلص المعتمد)
A43: ='مستخلص الشركة'!B6&" – "&'مستخلص الشركة'!C6 | B43: ='مستخلص الشركة'!I6 | C43: =B43*'مستخلص الشركة'!$F$29 | D43: =B43+C43 | E43: =TEXT('مستخلص الشركة'!H6,"#,##0.00")&" "&'مستخلص الشركة'!D6&" × "&TEXT('مستخلص الشركة'!F6,"#,##0")
A44: ='مستخلص الشركة'!B7&" – "&'مستخلص الشركة'!C7 | B44: ='مستخلص الشركة'!I7 | C44: =B44*'مستخلص الشركة'!$F$29 | D44: =B44+C44 | E44: =TEXT('مستخلص الشركة'!H7,"#,##0.00")&" "&'مستخلص الشركة'!D7&" × "&TEXT('مستخلص الشركة'!F7,"#,##0")
A45: ='مستخلص الشركة'!B8&" – "&'مستخلص الشركة'!C8 | B45: ='مستخلص الشركة'!I8 | C45: =B45*'مستخلص الشركة'!$F$29 | D45: =B45+C45 | E45: =TEXT('مستخلص الشركة'!H8,"#,##0.00")&" "&'مستخلص الشركة'!D8&" × "&TEXT('مستخلص الشركة'!F8,"#,##0")
...

Sheet مستخلص الرخام
A1: مستخلص أعمال الرخام – فيلا خاصة (الرياض)
A2: شركة الرخام (A | Marble Stone & Granite) – مقارنة كميات عرض السعر بالكميات المركبة فعلياً بالموقع
A4: المشروع | C4: فيلا خاصة – الرياض | G4: رقم المستخلص
A5: المقاول | C5: شركة الرخام – رخام وجرانيت | G5: تاريخ المستخلص
A6: عناية | C6: مدير المشروع | G6: نسبة ضريبة القيمة المضافة | I6: 0.15
A7: مرجع عرض السعر | C7: 1534/24
A8: تاريخ عرض السعر | C8: 13/11/2025
A10: م | B10: الدور | C10: الوصف | D10: النوع | E10: الوحدة | F10: سعر الوحدة (ر.س) | G10: كمية عرض السعر (م²) | H10: قيمة عرض السعر (ر.س) | I10: الكمية المركبة فعلياً (م²) | J10: قيمة الأعمال الفعلية (ر.س) | K10: فرق الكمية (م²) | L10: فرق القيمة (ر.س)
A11: 1 | B11: الأرضي G.F | C11: أرضيات ووزرات وسلالم | D11: رخام إيطالي مصقول 2 سم (بلوك 11791 / 11514) | E11: م² | G11: 380 | H11: =F11*G11 | J11: =F11*I11 | K11: =I11-G11 | L11: =J11-H11
A12: 2 | B12: الأول والثاني F.F / 2ND | C12: أرضيات ووزرات وسلالم | D12: رخام إيطالي مصقول 2 سم (بلوك 11791 / 11514) | E12: م² | G12: 375 | H12: =F12*G12 | J12: =F12*I12 | K12: =I12-G12 | L12: =J12-H12
A13: الإجمالي قبل الضريبة | G13: =SUM(G11:G12) | H13: =SUM(H11:H12) | I13: =SUM(I11:I12) | J13: =SUM(J11:J12) | K13: =SUM(K11:K12) | L13: =SUM(L11:L12)
A14: ="ضريبة القيمة المضافة "&TEXT($I$6,"0%") | H14: =H13*$I$6 | J14: =J13*$I$6 | L14: =J14-H14
A15: الإجمالي شامل الضريبة | H15: =H13+H14 | J15: =J13+J14 | L15: =J15-H15
A17: ملخص المستخلص
A18: البيان | G18: النسبة حسب العرض | H18: المفترض حسب عرض السعر (ر.س) | I18: الفعلي حسب المستخلص المعتمد وكشف الحسابات (ر.س)
A19: إجمالي قيمة الأعمال الفعلية شامل الضريبة | H19: =H15 | I19: ='مستخلص الشركة'!I30
A20: الدفعة الأولى المصروفة (2025-12-09) | G20: 0.7 | H20: =$H$15*G20 | I20: ='مستخلص الشركة'!I40
A21: الدفعتان الثانية والثالثة المصروفتان (2026-03-31 و 2026-05-03) | G21: 0.3 | H21: =$H$15*G21 | I21: ='مستخلص الشركة'!I41+'مستخلص الشركة'!I42
A22: إجمالي الدفعات السابقة المصروفة | G22: =SUM(G20:G21) | H22: =SUM(H20:H21) | I22: =SUM(I20:I21)
A23: صافي المستحق (موجب = مستحق للشركة / سالب = مسترد للمالك) | H23: =H19-H22 | I23: =I19-I22
A25: ملاحظة: الخلايا الصفراء مدخلات مطلوبة (الكميات المركبة فعلياً والمبالغ المصروفة). المصدر: عرض سعر شركة الرخام مرجع 1534/24 بتاريخ 13/11/2025.

Sheet مستخلص الشركة
A1: مراجعة مستخلص أعمال الرخام (كرارا) – فيلا سكنية – الرياض
A2: مقارنة الكميات المطالب بها من شركة الرخام بالكميات المعتمدة بعد مراجعة الموقع
A4: م | B4: القسم | C4: البند | D4: الوحدة | E4: الكمية حسب الشركة | F4: سعر الوحدة (ر.س) | G4: القيمة حسب الشركة (ر.س) | H4: الكمية المعتمدة | I4: القيمة المعتمدة (ر.س) | J4: الفرق (ر.س) | K4: ملاحظات | L4: القيمة حسب المستخلص المحدث 27/9/2026 (ر.س) | M4: المطابقة مع المعتمد (I)
A5: ملحق علوي
A6: 1 | B6: ملحق علوي | C6: أرضيات الملحق العلوي (تم التوريد) | D6: M² | E6: 70 | G6: =E6*F6 | H6: 70 | I6: =H6*F6 | J6: =I6-G6 | M6: =IF(ROUND(L6-I6,2)=0,"مطابق","فرق "&TEXT(L6-I6,"#,##0.00"))
A7: 2 | B7: ملحق علوي | C7: أرضيات الملحق العلوي - مكرر (تم التوريد) | D7: M² | E7: 70 | G7: =E7*F7 | H7: 70 | I7: =H7*F7 | J7: =I7-G7 | K7: الرخام المرتجع (مكسور + مكرر) تم استخدامه في 20 م² من درج الأول للعلوي – تم خصمه في المستخلص المحدث 27/9/2026 | M7: =IF(ROUND(L7-I7,2)=0,"مطابق","فرق "&TEXT(L7-I7,"#,##0.00"))
A8: 3 | B8: ملحق علوي | C8: نعلات الملحق العلوي 17 سم ديكور رقم 1 | D8: M² | E8: 6.8 | G8: =E8*F8 | H8: 6.8 | I8: =H8*F8 | J8: =I8-G8 | K8: لم يتم التوريد | M8: =IF(ROUND(L8-I8,2)=0,"مطابق","فرق "&TEXT(L8-I8,"#,##0.00"))
A9: 4 | B9: ملحق علوي | C9: أجور ديكور | D9: LM | E9: 40 | G9: =E9*F9 | H9: 40 | I9: =H9*F9 | J9: =I9-G9 | M9: =IF(ROUND(L9-I9,2)=0,"مطابق","فرق "&TEXT(L9-I9,"#,##0.00"))
B10: ملحق علوي | C10: خصم رخام مكسور قابل للاستخدام (من المرتجع) | D10: M² | E10: 0 | F10: =F7 | G10: =E10*F10 | H10: 0 | I10: =-H10*F10 | J10: =I10-G10 | K10: الخصم (20 م²) مُطبّق على بند درج الأول للعلوي (صف 25) بدل هذا البند | L10: 0 | M10: =IF(ROUND(L10-I10,2)=0,"مطابق","فرق "&TEXT(L10-I10,"#,##0.00"))
A11: إجمالي ملحق علوي | G11: =SUM(G6:G10) | I11: =SUM(I6:I10) | J11: =SUM(J6:J10) | L11: =SUM(L6:L10) | M11: =IF(ROUND(L11-I11,2)=0,"مطابق","فرق "&TEXT(L11-I11,"#,##0.00"))
A12: دور أول
A13: 5 | B13: دور أول | C13: أرضيات الدور الأول (تم التوريد) | D13: M² | E13: 43 | G13: =E13*F13 | H13: 43 | I13: =H13*F13 | J13: =I13-G13 | M13: =IF(ROUND(L13-I13,2)=0,"مطابق","فرق "&TEXT(L13-I13,"#,##0.00"))
A14: 6 | B14: دور أول | C14: نعلات الدور الأول 17 سم ديكور رقم 1 | D14: M² | E14: 7.99 | G14: =E14*F14 | H14: 7.99 | I14: =H14*F14 | J14: =I14-G14 | K14: لم يتم التوريد | M14: =IF(ROUND(L14-I14,2)=0,"مطابق","فرق "&TEXT(L14-I14,"#,##0.00"))
A15: 7 | B15: دور أول | C15: أجور ديكور | D15: LM | E15: 47 | G15: =E15*F15 | H15: 47 | I15: =H15*F15 | J15: =I15-G15 | M15: =IF(ROUND(L15-I15,2)=0,"مطابق","فرق "&TEXT(L15-I15,"#,##0.00"))
A16: إجمالي دور أول | G16: =SUM(G13:G15) | I16: =SUM(I13:I15) | J16: =SUM(J13:J15) | L16: =SUM(L13:L15) | M16: =IF(ROUND(L16-I16,2)=0,"مطابق","فرق "&TEXT(L16-I16,"#,##0.00"))
A17: القبو
A18: 8 | B18: القبو | C18: أرضيات القبو (تم التوريد) | D18: M² | E18: 150 | G18: =E18*F18 | H18: 150 | I18: =H18*F18 | J18: =I18-G18 | M18: =IF(ROUND(L18-I18,2)=0,"مطابق","فرق "&TEXT(L18-I18,"#,##0.00"))
A19: 9 | B19: القبو | C19: نعلات القبو 17 سم ديكور رقم 1 | D19: M² | E19: 18.53 | G19: =E19*F19 | H19: 18.53 | I19: =H19*F19 | J19: =I19-G19 | K19: لم يتم التوريد | M19: =IF(ROUND(L19-I19,2)=0,"مطابق","فرق "&TEXT(L19-I19,"#,##0.00"))
A20: 10 | B20: القبو | C20: أجور ديكور | D20: LM | E20: 109 | G20: =E20*F20 | H20: 109 | I20: =H20*F20 | J20: =I20-G20 | M20: =IF(ROUND(L20-I20,2)=0,"مطابق","فرق "&TEXT(L20-I20,"#,##0.00"))
A21: إجمالي القبو | G21: =SUM(G18:G20) | I21: =SUM(I18:I20) | J21: =SUM(J18:J20) | L21: =SUM(L18:L20) | M21: =IF(ROUND(L21-I21,2)=0,"مطابق","فرق "&TEXT(L21-I21,"#,##0.00"))
A22: الأدراج
A23: 11 | B23: الأدراج | C23: درج من الأرضي إلى القبو - كرارا | D23: M² | E23: 25.88 | G23: =E23*F23 | H23: 25.88 | I23: =H23*F23 | J23: =I23-G23 | K23: لم يتم التوريد | M23: =IF(ROUND(L23-I23,2)=0,"مطابق","فرق "&TEXT(L23-I23,"#,##0.00"))
A24: 12 | B24: الأدراج | C24: أعمال فنية للدرج من الأرضي للقبو | D24: LM | E24: 87.4 | G24: =E24*F24 | H24: 87.4 | I24: =H24*F24 | J24: =I24-G24 | K24: لم يتم التوريد | M24: =IF(ROUND(L24-I24,2)=0,"مطابق","فرق "&TEXT(L24-I24,"#,##0.00"))
A25: 13 | B25: الأدراج | C25: درج من الأول إلى العلوي - كرارا | D25: M² | E25: 27.53 | G25: =E25*F25 | H25: 7.53 | I25: =H25*F25 | J25: =I25-G25 | K25: 27.53 م² منها 20 م² من الرخام المرتجع → المحتسب 7.53 م² فقط | M25: =IF(ROUND(L25-I25,2)=0,"مطابق","فرق "&TEXT(L25-I25,"#,##0.00"))
A26: 14 | B26: الأدراج | C26: أعمال فنية للدرج من الأول إلى العلوي | D26: LM | E26: 100.94 | G26: =E26*F26 | H26: 100.94 | I26: =H26*F26 | J26: =I26-G26 | K26: لم يتم التوريد | M26: =IF(ROUND(L26-I26,2)=0,"مطابق","فرق "&TEXT(L26-I26,"#,##0.00"))
A27: إجمالي الأدراج | G27: =SUM(G23:G26) | I27: =SUM(I23:I26) | J27: =SUM(J23:J26) | L27: =SUM(L23:L26) | M27: =IF(ROUND(L27-I27,2)=0,"مطابق","فرق "&TEXT(L27-I27,"#,##0.00"))
A28: الإجمالي قبل الضريبة | G28: =G11+G16+G21+G27 | I28: =I11+I16+I21+I27 | J28: =J11+J16+J21+J27 | L28: =L11+L16+L21+L27 | M28: =IF(ROUND(L28-I28,2)=0,"مطابق","فرق "&TEXT(L28-I28,"#,##0.00"))
A29: ضريبة القيمة المضافة | F29: 0.15 | G29: =G28*$F$29 | I29: =I28*$F$29 | J29: =I29-G29 | L29: =L28*$F$29 | M29: =IF(ROUND(L29-I29,2)=0,"مطابق","فرق "&TEXT(L29-I29,"#,##0.00"))
A30: الإجمالي العام شامل الضريبة | G30: =G28+G29 | I30: =I28+I29 | J30: =I30-G30 | L30: =L28+L29 | M30: =IF(ROUND(L30-I30,2)=0,"مطابق","فرق "&TEXT(L30-I30,"#,##0.00"))
A32: الدفعات المحصلة (المدفوع للشركة) | I32: =I43 | J32: =I32-G32 | K32: الشركة (G) محتسبة دفعتين فقط – المعتمد (I) من كشف الحسابات | M32: =IF(ROUND(L32-I32,2)=0,"مطابق","فرق "&TEXT(L32-I32,"#,##0.00"))
A33: الرصيد المتاح لصالح المالك (المدفوع – قيمة الأعمال) | G33: =G32-G30 | I33: =I32-I30 | J33: =I33-G33 | L33: =L32-L30 | M33: =IF(ROUND(L33-I33,2)=0,"مطابق","فرق "&TEXT(L33-I33,"#,##0.00"))
A34: الرصيد كما ورد في مستخلص الشركة (للمطابقة) | K34: =IF(ROUND(G34-G33,2)=0,"مطابق","غير مطابق")
A35: الرصيد بعد إضافة الدفعة المنسية فقط (بأعمال الشركة كما هي) | G35: =I32-G30
A38: الدفعات المحولة من العميل لشركة الرخام (حسب كشف الحسابات)
A39: م | B39: التاريخ | C39: البيان | G39: القيمة قبل الضريبة (ر.س) | H39: الضريبة (ر.س) | I39: الإجمالي (ر.س) | J39: مذكورة في مستخلص الشركة؟ | K39: ملاحظات
A40: 1 | B40: =DATE(2025,12,9) | C40: دفعة أولى 50% – توريد الرخام الداخلي | H40: =G40*$F$29 | I40: =G40+H40 | J40: نعم
A41: 2 | B41: =DATE(2026,3,31) | C41: دفعة 2 – توريد الرخام الداخلي (رصيد ك ح) | H41: =G41*$F$29 | I41: =G41+H41 | J41: لا | K41: دفعة غير محتسبة في مستخلص الشركة
A42: 3 | B42: =DATE(2026,5,3) | C42: دفعة 3 – توريد الرخام الداخلي (الدور الثاني) | H42: =G42*$F$29 | I42: =G42+H42 | J42: نعم
A43: إجمالي الدفعات | G43: =SUM(G40:G42) | H43: =SUM(H40:H42) | I43: =SUM(I40:I42)
A44: الدفعات المحتسبة في مستخلص الشركة | I44: =SUMIF(J40:J42,"نعم",I40:I42) | K44: =IF(ROUND(I44-G32,2)=0,"يطابق المحصّل حسب الشركة","لا يطابق")
...

Sheet أعمال الأرضي المتبقية
A1: أعمال الدور الأرضي المتبقية – فيلا سكنية – الرياض
A3: م | B3: البند | C3: المورد / المصدر | D3: الوحدة | E3: الكمية | F3: سعر الوحدة (ر.س) | G3: القيمة قبل الضريبة (ر.س) | H3: ملاحظات
A4: أولاً: التوريد
A5: 1 | B5: رخام كالكتا إيطالي – نخب أول – ألواح خام سماكة 2 سم (النوع 1) – أرضيات ودرج وجدران مداخل المجالس | C5: مورد الرخام (عرض سعر 29/09/2026 لشركة الرخام) | D5: M² | E5: 346.8 | G5: =E5*F5
A6: 2 | B6: رخام كالكتا إيطالي – نخب أول – ألواح خام سماكة 2 سم (النوع 2) – أرضيات وجدران الحمامات | C6: مورد الرخام (عرض سعر 29/09/2026 لشركة الرخام) | D6: M² | E6: 60.39 | G6: =E6*F6
A7: إجمالي التوريد | G7: =SUM(G5:G6)
A8: ثانياً: القص والتركيب
A9: 3 | B9: قص الرخام + تركيب ناشف + سيلر + تغليف + توصيل (Marble Cutting, Dry lay, Sealer, Packing, Delivery) | C9: شركة القص والتركيب (عرض 21/09/2026) | D9: M² | E9: 350 | G9: =E9*F9 | H9: شروط الدفع: 100% مقدم
A10: 4 | B10: أعمال فنية / تشكيل (Fabrication) | C10: شركة القص والتركيب (عرض 21/09/2026) | D10: LM | E10: 110 | G10: =E10*F10
A11: 5 | B11: مجرى مزدوج وإضاءة (Double Groove & Light) | C11: شركة القص والتركيب (عرض 21/09/2026) | D11: LM | E11: 111 | G11: =E11*F11
A12: إجمالي القص والتركيب | G12: =SUM(G9:G11)
A14: إجمالي أعمال الأرضي قبل الضريبة | G14: =G7+G12
A15: ضريبة القيمة المضافة | F15: ='مستخلص الشركة'!F29 | G15: =G14*F15
A16: إجمالي أعمال الأرضي المتبقية شامل الضريبة | G16: =G14+G15
A18: ملاحظة: عرض القص والتركيب من شركة القص والتركيب بتاريخ 21/09/2026 (مرجع 1534/24) – الدفع 100% مقدم.
A19: ="ملاحظة: عرض التوريد صادر من مورد الرخام إلى شركة الرخام بتاريخ 29/09/2026: "&TEXT(E5,"#,##0.00")&" م² × "&TEXT(F5,"#,##0")&" + "&TEXT(E6,"#,##0.00")&" م² × "&TEXT(F6,"#,##0")&" = "&TEXT(G7,"#,##0")&" + ضريبة "&TEXT(G7*F15,"#,##0")&" = "&TEXT(G7*(1+F15),"#,##0")&" ر.س."
