Workbook

Sheet المقدمة
B2: هيكلة وإدارة أعمال تشطيب فيلا سكنية خاصة
B3: ملف متابعة تنفيذى | التصميم • الاعتمادات • التوريدات • البرنامج الزمنى • ملاحظات الموقع
B5: بيانات المشروع
B6: إعداد | D6: م مصطفى طه
B7: الدور فى المشروع | D7: مدير مشروع تجهيزات داخلية (Fit-Out)
B8: نوع المشروع | D8: تشطيبات وتصميم داخلى – فيلا سكنية خاصة
B9: فترة البرنامج الزمنى | D9: ="من "&TEXT('جدول زمنى'!B2,"dd/mm/yyyy")&" إلى "&TEXT('جدول زمنى'!D2,"dd/mm/yyyy") -> من 07/09/2026 إلى 18/10/2026
B10: عدد أنشطة البرنامج الزمنى | D10: ='جدول زمنى'!I2 -> 56
B11: عدد جداول التوريد | D11: =ملخص!C15 -> 14
B12: نسبة الإنجاز الحالية (لوحة المتابعة) | D12: =ملخص!G16 -> 0.35294118
B14: نبذة عن المشروع
B15: يعرض هذا الملف منهجية متكاملة لإدارة المرحلة النهائية من مشروع تشطيب وتصميم داخلى لفيلا سكنية خاصة؛ بدءاً من حصر التعديلات على التصميم واعتماد الخامات وطرق التنفيذ، مروراً بحصر جداول التوريدات بالمواصفات والصور، وصولاً إلى خطة الأعمال المتبقية والبرنامج الزمنى التنفيذى ومتابعة ملاحظات زيارات الموقع.
B17: أهداف الملف
B18: • توحيد مصدر المعلومات لكل أطراف المشروع (التصميم – التنفيذ – التوريد – العميل)
B19: • متابعة حالة كل بند (منتهى / قيد التنفيذ / معلق) وحالة اعتماد العميل
B20: • ربط التوريدات والأعمال المتبقية ببرنامج زمنى واضح بمخطط أسبوعى
B21: • قياس نسبة الإنجاز تلقائياً من خلال لوحة متابعة مرتبطة بالجداول
B23: منهجية العمل
B24: 1 الحصر | C24: 2 الاعتماد | D24: 3 التوريد | E24: 4 التخطيط | F24: 5 الجدولة | G24: 6 المتابعة
B25: التعديلات المطلوبة على التصميم | C25: الخامات وطرق التنفيذ | D25: جداول بالمواصفات والصور | E25: الأعمال المتبقية بالموقع | F25: برنامج زمنى أسبوعى | G25: ملاحظات الموقع ونسبة الإنجاز
B27: دليل ألوان الحالات
B28: منتهى / تم | C28: قيد التنفيذ | D28: معلق | E28: لم يبدأ | F28: بانتظار الموعد
B30: ملاحظة: تم إخفاء اسم العميل وبعض البيانات حفاظاً على خصوصية المشروع. للانتقال بين أقسام الملف استخدم شيت «الفهرس».
B31: ◀ الانتقال إلى الفهرس

Sheet الفهرس
B2: فهرس محتويات الملف
B4: م | C4: القسم | D4: المحتوى | E4: عدد البنود
B5: 1 | C5: المقدمة | D5: نبذة عن المشروع، أهداف الملف، منهجية العمل ودليل ألوان الحالات | E5: —
B6: 2 | C6: ملخص الهيكلة ولوحة الإنجاز | D6: هيكلة الخطة ولوحة متابعة نسب الإنجاز لكل قسم | E6: =ملخص!C16 -> 68
B7: 3 | C7: تعديلات التصميم | D7: حصر التعديلات على التصميم حسب الفراغ والمسؤول وحالة اعتماد العميل | E7: =ملخص!C12 -> 19
B8: 4 | C8: التعميدات | D8: اعتماد الخامات وطرق التنفيذ والموردين والعينات المعتمدة | E8: =ملخص!C13 -> 18
B9: 5 | C9: جداول التوريدات | D9: ملخص جداول التوريد مع جداول تفصيلية بالمواصفات والأبعاد والصور | E9: =ملخص!C15 -> 14
B10: 6 | C10: خطة العمل | D10: الأعمال المتبقية قبل توريد الأثاث مقسمة حسب التخصص | E10: —
B11: 7 | C11: البرنامج الزمنى | D11: برنامج زمنى تنفيذى لمدة 6 أسابيع بمخطط أسبوعى (Gantt) | E11: ='جدول زمنى'!I2 -> 56
B12: 8 | C12: ملاحظات الموقع | D12: ملاحظات زيارة الموقع والإجراء المطلوب وحالة كل ملاحظة | E12: =ملخص!C14 -> 17
B13: 9 | C13: عرض السجاد والموكيت | D13: جدول تفصيلى للسجاد والموكيت بالمقاسات والأسعار والصور | E13: =COUNTA('السجاد - الصين'!B3:B21) -> 19
B15: اضغط على اسم القسم للانتقال إليه، ومن أى شيت اضغط «↩ الفهرس» للرجوع هنا.

Sheet ملخص
A1: هيكلة أعمال فيلا سكنية خاصة | K1: ↩ الفهرس
A2: م | B2: هيكلة الخطة
A3: 1 | B3: حصر التعديلات على التصميم
A4: 2 | B4: حصر كافة التعميدات (خامات - طريقة تنفيذ)
A5: 3 | B5: حصر كافة التوريدات (جداول)
A6: 4 | B6: خطة للعمل كاملة حتى النهاية (بناء على المتبقى من اعمال بالموقع)
A7: 5 | B7: جدول زمنى للمشروع
A8: 6 | B8: خطة لاعمال يونايت اكس فى الموقع
B10: لوحة متابعة الإنجاز
B11: القسم | C11: إجمالى البنود | D11: منتهى | E11: قيد التنفيذ | F11: معلق | G11: نسبة الإنجاز
B12: تعديلات التصميم | C12: =COUNTA('تعديلات التصميم'!$B$3:$B$21) -> 19 | D12: =COUNTIF('تعديلات التصميم'!$F$3:$F$21,D$11) -> 10 | E12: =COUNTIF('تعديلات التصميم'!$F$3:$F$21,E$11) -> 8 | F12: =COUNTIF('تعديلات التصميم'!$F$3:$F$21,F$11) -> 0 | G12: =IFERROR(D12/C12,0) -> 0.52631579
B13: التعميدات | C13: =COUNTA(التعميدات!$B$3:$B$20) -> 18 | D13: =COUNTIF(التعميدات!$H$3:$H$20,D$11) -> 8 | E13: =COUNTIF(التعميدات!$H$3:$H$20,E$11) -> 8 | F13: =COUNTIF(التعميدات!$H$3:$H$20,F$11) -> 1 | G13: =IFERROR(D13/C13,0) -> 0.44444444
B14: ملاحظات الموقع | C14: =COUNTA(ملاحظات!$B$3:$B$19) -> 17 | D14: =COUNTIF(ملاحظات!$E$3:$E$19,D$11) -> 1 | E14: =COUNTIF(ملاحظات!$E$3:$E$19,E$11) -> 11 | F14: =COUNTIF(ملاحظات!$E$3:$E$19,F$11) -> 4 | G14: =IFERROR(D14/C14,0) -> 0.058823529
B15: جداول التوريدات (حصر مكتمل) | C15: =COUNTA('جداول التوريدات'!$B$3:$B$18) -> 14 | D15: =COUNTIF('جداول التوريدات'!$G$3:$G$18,"مكتمل") -> 5 | E15: =C15-D15 -> 9 | F15: - | G15: =IFERROR(D15/C15,0) -> 0.35714286
B16: الإجمالى | C16: =SUM(C12:C15) -> 68 | D16: =SUM(D12:D15) -> 24 | E16: =SUM(E12:E15) -> 36 | F16: =SUM(F12:F14) -> 5 | G16: =IFERROR(D16/C16,0) -> 0.35294118

Sheet تعديلات التصميم
A1: حصر التعديلات على التصميم | I1: ↩ الفهرس
A2: م | B2: الفراغ / المكان | C2: التعديل / التصميم المطلوب | D2: المسؤول | E2: تاريخ الانتهاء | F2: الحالة | G2: اعتماد العميل | H2: ملاحظات
A3: 1 | B3: غرفة الحارس | C3: اعادة توزيع غرفة الحارس بما يتماشى مع متطلبات العميل : يتضمن التالي ( مكان للشنطة - مكان للطبخ وشفط - الاسره 2 فوق بعض دبل - جلسة لأكل عدد 2 - دولابين ملابس كل واحد بقفل ومكان لللشنط للتخزين - التصميم ستاندر جداا وغير مكلف ومستدام مثال اسرة حديد ) | D3: المصمم الداخلي | F3: منتهى | G3: تم
A4: 2 | B4: حمام غرفة البنت | C4: حمام غرفة البنت بحيث يستوعب اكبر عدد من الرفوف بالاعتماد على اخر مقترح معتمد | D4: المصمم الداخلي | F4: منتهى | G4: تم
A5: 3 | B5: غرفة ملابس الماستر | C5: التصميم الداخلى لدولاب غرفة الملابس | D5: المصممة الداخلية | F5: منتهى | G5: قيد الانتظار | H5: بها تعديل من العميل يحتاج اعتماد
A6: 4 | B6: غرف الملابس | C6: تصميمى داخلى لغرف الملابس | D6: المصمم الداخلي | F6: منتهى | G6: قيد الانتظار | H6: بها تعديل من العميل يحتاج اعتماد
A7: 5 | B7: غرفة الخادمات | C7: تكون تكلفة غرف النوم تكلفه اقل - تعديل التصميم ثلاث دواليب كل دولاب قفل بمفتاح حجم كبير - ثلاث اسرة واحد منه متحرك على الجدار ووضع مكانه طاولة | D7: المصمم الداخلي | F7: منتهى | G7: قيد الانتظار
A8: 6 | B8: غرفة الغسيل | C8: تصميم نهائى لغرفة الغسيل | D8: المصمم الداخلي | F8: قيد التنفيذ
A9: 7 | B9: مستودع المطبخ | C9: تصميم نهائى لمستودع المطبخ | D9: المصمم الداخلي | F9: قيد التنفيذ
A10: 8 | B10: مستودع القبو | C10: تصميم نهائى لمستودع القبو | D10: المصمم الداخلي | F10: قيد التنفيذ
A11: 9 | B11: المصعد | C11: داخلى المصعد خيار | F11: منتهى | G11: تم
A12: 10 | B12: مغاسل القبو | C12: خيار 2 | F12: منتهى | G12: تم
A13: 11 | B13: حمام الرجال | C13: الغاء مرايا امام الشباك و تغيير الاضاءة | F13: منتهى
A14: 12 | B14: غرفة الغسيل | C14: اعادة تصميم كامل | F14: قيد التنفيذ
A15: 13 | B15: مستودع المطبخ | C15: اعادة تصميم كامل | F15: قيد التنفيذ | H15: طلبات العميل
A16: 14 | B16: مستودع القبو | C16: اعادة تصميم كامل | F16: منتهى | G16: تم | H16: فى انتظار اعتماد تصميم العمود الخاص بالدرج
A17: 15 | B17: المكتب | C17: تعديل الخزائن و تحويلها لتكسية و تعديل توجيه المكتب | D17: المصمم الداخلي | F17: قيد التنفيذ
A18: 16 | B18: غرفة الطعام | C18: اعتماد مخطط غرفة الطعام لتصنيع الاثاث | D18: المصمم الداخلي | F18: منتهى | G18: تم | H18: متبقى اعتماد كرسي
A19: 17 | B19: الواجهه الخارجية | C19: اعتماد تصميم لكورنر الفيلا منطقة حوض الزرع | D19: مصمم الواجهات | F19: قيد التنفيذ
A20: 18 | B20: غرفة الملحق | C20: تفسيم دواليب الملابس بها | D20: المصمم الداخلي | F20: قيد التنفيذ
A21: 19 | B21: غرفة ملابس الملحق | C21: تحويلها لمستودع برفوف | D21: المصمم الداخلي

Sheet التعميدات
A1: حصر كافة التعميدات (خامات - طريقة تنفيذ) | K1: ↩ الفهرس
A2: م | B2: البند / التعميد | C2: النوع | D2: المورد | E2: العينة المعتمدة | F2: المسؤول | G2: تاريخ الاعتماد | H2: الحالة | I2: اعتماد العميل | J2: ملاحظات
A3: 1 | B3: بلاط الاحواش و بلاط حوش القبو | C3: خامة + طريقة تنفيذ | D3: راس الخيمة | E3: بلاطتين لون رمادى و بيج 120*60 يتم قصها كل 20 سم | H3: منتهى | I3: تم | J3: تم التوريد و اعتماد طريقة تنفيذ سيتم عمل عينة قى انتظار الانتهاء من العزل
A4: 2 | B4: بلاط جدران القبو | C4: خامة + طريقة تنفيذ | D4: ابيات | E4: بلاط 120*120 او مخصوص حسب وقت التوريد | F4: مهندس الموقع | H4: منتهى | I4: تم | J4: تم التعميد ننتظر التحويل لابيات و التوريد
A5: 3 | B5: درابزين الدرج | C5: طريقة تنفيذ | D5: عروض اسعار | E5: زاوية معدن تركب جانبيه | F5: مصطفى | H5: قيد التنفيذ | J5: فى انتظار باقى عروض الاسعار يوجد عرض سعر متبقى الاخر
A6: 4 | B6: درابزين البلكونات | C6: طريقة تنفيذ | D6: عروض اسعار | E6: زاوية مخفية مع زجاج اسود | F6: مصطفى | H6: قيد التنفيذ
A7: 5 | B7: درابزين البهو الداخلى | C7: طريقة تنفيذ | D7: عروض اسعار | E7: زاوية معدن تركب جانبيه | F7: مصطفى | H7: قيد التنفيذ
A8: 6 | B8: رخام ارضيات الدور الارضى | C8: طريقة تنفيذ | D8: A MARBLE | E8: مخطط تبليط | F8: مهندس الموقع | H8: قيد التنفيذ | J8: مشكلة فى توريد البلاط (سيتم الاجتماع مع الشركة غدا الموقع)
A9: 7 | B9: عينة حمام متبلط كامل | C9: طريقة تنفيذ | D9: مقاول التبليط | E9: تم | F9: مهندس الموقع | H9: قيد التنفيذ | J9: فى انتظار انتهاء تركيب المغسلة و تركيب الاكسسوارات
A10: 8 | B10: عينة قشرة لبداية اعمال الخشب و الابواب | C10: خامة | D10: UNIT X | E10: بورد به 6 عينات | F10: مهندس التشطيبات | H10: منتهى | I10: تم | J10: تم تغيير عينة القشرة لان بها مشاكل
A11: 9 | B11: اعتماد تركيب رخام الدرج باحد الطرق و علاقته مع الليد | C11: طريقة تنفيذ | D11: A MARBLE | E11: اعتماد طريقة من المرسلة بواسطة المصنع | F11: مهندس التشطيبات | H11: منتهى | J11: سيتم عمل عينة مع فرزة و اعتمادها
A12: 10 | B12: اعتماد شكل للنعله الرخام | C12: طريقة تنفيذ | D12: A MARBLE | E12: تم ارسال عينات للاعتماد | F12: مهندس التشطيبات | H12: قيد التنفيذ
A13: 11 | B13: مخططات تنفيذ الاعمال الخشبية غرف النوم | C13: خامة + طريقة تنفيذ | F13: مصطفى | H13: منتهى | I13: قيد الانتظار
A14: 12 | B14: اعتماد عينة باركيه لارضيات غرف النوم | C14: خامة | H14: قيد التنفيذ | J14: تم وصول عينات ابيات متبقي الفارس و هاتش
A15: 13 | B15: اعتماد خيار مغسلة صالة الملحق العلوى | H15: معلق | I15: قيد الانتظار
A16: 14 | B16: الحاجز الخشبي | C16: خامة + طريقة تنفيذ | H16: منتهى | I16: تم | J16: تم اعاتماد خيار 3 مع لكسان خلفى
A17: 15 | B17: تلبيس خلفية للباب الرئيسى معبره خشب | C17: طريقة تنفيذ
A18: 16 | B18: عينة تركيب جدران القبو | C18: طريقة تنفيذ | E18: تم | F18: مهندس الموقع | H18: منتهى | I18: قيد الانتظار | J18: انتظار تعميد العميل
A19: 17 | B19: عينة البروفايل للدهان | C19: طريقة تنفيذ | E19: تم | F19: مهندس الموقع | H19: منتهى | I19: قيد الانتظار | J19: انتظار تعميد العميل
A20: 18 | B20: اعتماد مصنع من مصاانع السجاد | D20: الصين | H20: قيد التنفيذ | J20: تم ارسال عرضين سعر للعميل

Sheet جداول التوريدات
A1: ملخص جداول التوريدات | L1: ↩ الفهرس
A2: م | B2: البند | E2: الموردين | F2: المسؤول | G2: حالة الحصر | H2: الجدول
A3: 1 | B3: الكنب و الجلسات و التنجيد | G3: جاري الحصر | H3: ◀ افتح الجدول
A4: 2 | B4: غرف الطعام | G4: مكتمل | H4: ◀ افتح الجدول
A5: 3 | B5: السجاد و الموكيت | G5: مكتمل | H5: ◀ افتح الجدول
A6: 4 | B6: توريد الاعمال الخشبية المتبقيه بعد التعديل يونت اكس | G6: جاري الحصر | H6: ◀ افتح الجدول
A7: 5 | B7: النجف و الانارات | H7: ◀ افتح الجدول
A8: 6 | B8: الستائر | H8: ◀ افتح الجدول
A9: 7 | B9: المغاسل | G9: مكتمل | H9: ◀ افتح الجدول
A10: 8 | B10: المغاسل ملحقات | G10: مكتمل | H10: ◀ افتح الجدول
A11: 9 | B11: اكسسورارت السباكة | H11: ◀ افتح الجدول
A12: 10 | B12: ورق الجدران | H12: ◀ افتح الجدول
A13: 11 | B13: المرايا و الزجاج | G13: مكتمل | H13: ◀ افتح الجدول
A14: 12 | B14: النباتات الصناعية | H14: ◀ افتح الجدول
A15: 13 | B15: طاولات الجلسات | H15: ◀ افتح الجدول
A16: 14 | B16: اللوحات الجدارية | H16: ◀ افتح الجدول
A17: 15 | H17: ◀ افتح الجدول
A18: 16 | H18: ◀ افتح الجدول
A21: ="جدول رقم "&A3&" - "&B3 -> جدول رقم 1 - الكنب و الجلسات و التنجيد | K21: ▲ رجوع للفهرس
A22: م | B22: المواصفات | C22: الكمية | D22: الموقع | E22: الابعاد | F22: الخامات | G22: المورد | H22: سعر الوحدة | I22: الاجمالى | J22: الصورة التوضيحية
A23: 1 | B23: سرير غرفة الماستر مع هيدبورد خلفى تنجيد | C23: 1 | D23: غرفة الماستر | E23: مقاس السرير 185*210 مقاس الهيدبورد 410*100 مقاس المرتبة 175*200 | F23: خشب سوليد قماش
A24: 2 | B24: كرسي مفرد تنجيد | C24: 2 | D24: غرفة الماستر | E24: 80*77 | F24: خشب سوليد قماش
A25: 3 | B25: جلسة تنجيد كابوتنيه قماش | C25: 1 | D25: غرفة الماستر | E25: 250*95 | F25: خشب سوليد قماش
A26: 4 | B26: كرسى تسريحة تنجيد مع نعلة استانلس ذهبي | C26: 1 | D26: غرفة الماستر | E26: قطر 60 سم | F26: خشب سوليد قماش استانلس ذهبى
A27: 5 | B27: سرير تنجيد قماش مع حلايا استانلس ذهبى | C27: 1 | D27: غرفة نوم 1 | E27: 170*215 | F27: خشب سوليد قماش استانلس ذهبى
A28: 6 | B28: كرسى تسريحة تنجيد مع نعلة استانلس ذهبي | C28: 1 | D28: غرفة نوم 2 | E28: قطر 60 سم | F28: خشب سوليد قماش استانلس ذهبى
A29: 7 | C29: 1 | D29: غرفة نوم 3 | F29: خشب سوليد قماش
A30: 8
A31: 9
A32: 10
A33: 11
A34: 12
A35: 13
A36: 14
A37: 15
A38: 16
A39: 17
A41: ="جدول رقم "&A4&" - "&B4 -> جدول رقم 2 - غرف الطعام | K41: ▲ رجوع للفهرس
A42: م | B42: المواصفات | C42: الكمية | D42: الموقع | E42: الابعاد | F42: الخامات | G42: المورد | H42: سعر الوحدة | I42: الاجمالى | J42: الصورة التوضيحية
A43: 1 | B43: طاولة طعام سطح رخام مع قاعدة خشب ملبس استانلستيل فضى شرائح حسب التصميم | C43: 2 | D43: غرفة طعام الارضى | E43: 200*100 | F43: خشب رخام استانلس
...

Sheet خطه العمل
A1: الأعمال المتبقية قبل توريد الأثاث | F1: ↩ الفهرس
A2: تعديلات معمارية
A3: م | B3: البيان | C3: المسؤول | D3: الحالة | E3: ملاحظات
A4: 1 | B4: ارتفاعات فتحات الابواب (تحديد مقاس فتحة الابواب الداخلية) | C4: مهندس الموقع | D4: تم
A5: 2 | B5: تعديل صبة الدرج للتبليط
A6: 3 | B6: تعديل فتحة باب الدرج
A7: 4 | B7: تقفيل الرصيف و صب الدرجات الخارجية و الانترلوك
A8: 5 | B8: صب الدرج الخلفى لباب الدرج
A9: 6 | B9: صب درجات المداخل فى الاحواش
A10: 7
A11: 8
A12: السباكة
A13: م | B13: البيان | C13: المسؤول | D13: الحالة | E13: ملاحظات
A14: 1 | B14: انهاء تمديد سباكة الاحواض كاملة فى الخارجى و القبو | D14: تم
A15: 2 | B15: تمديد سباكة الحمامات
A16: 3
A17: 4
A18: 5
A19: الكهربا
A20: م | B20: البيان | C20: المسؤول | D20: الحالة | E20: ملاحظات
A21: 1 | B21: توصيل الكهرباء من العمومى
A22: 2
A23: 3
A24: 4
A25: 5
A26: تمديدات الشفط
A27: م | B27: البيان | C27: المسؤول | D27: الحالة | E27: ملاحظات
A28: 1 | B28: هود للقبو | D28: تم
A29: 2 | B29: مراوح الشفط فى الحمامات و المطبخ العلوى | D29: جار التنفيذ
A30: 3
A31: 4
A32: 5
A33: الجبس
A34: م | B34: البيان | C34: المسؤول | D34: الحالة | E34: ملاحظات
A35: 1 | B35: تعديل دولاب العبايات ليتوافق مع ارتفاع الابواب فى الدور الارضي | C35: مقاول جبس
A36: 2 | B36: استكمال اعمال البانوهات فى باقى الفيلا | C36: مقاول جبس
A37: 3 | B37: جبس بورد الحمامات | C37: مقاول جبس | D37: تم عمل عينة للحمام
A38: 4 | B38: جبس بورد صالة الارضى بالتنسيق مع النجار | C38: مقاول جبس | D38: تم
A39: 5 | B39: ديكور تلفزيون غرفة النوم (يحتاج حديد تدعيم) | C39: مقاول جبس
A40: الحدادة
...

Sheet جدول زمنى
A1: فيلا سكنية خاصة – البرنامج الزمنى التنفيذى (6 أسابيع) | P1: ↩ الفهرس
B2: 46272 | D2: =$B$2+41 -> 46313 | I2: =COUNTA($B$7:$B$62) -> 56 | K2: =IFERROR(AVERAGE($H$7:$H$62),0) -> 0
A4: بيانات النشاط | J4: المخطط الزمنى – أسابيع
J5: =$B$2 -> 46272 | K5: =J5+7 -> 46279 | L5: =K5+7 -> 46286 | M5: =L5+7 -> 46293 | N5: =M5+7 -> 46300 | O5: =N5+7 -> 46307
A6: م | B6: النشاط | C6: المسار | D6: المسؤول | E6: البداية | F6: النهاية | G6: المدة (يوم) | H6: الإنجاز | I6: الحالة | J6: ="أسبوع 1" -> أسبوع 1 | K6: ="أسبوع 2" -> أسبوع 2 | L6: ="أسبوع 3" -> أسبوع 3 | M6: ="أسبوع 4" -> أسبوع 4 | N6: ="أسبوع 5" -> أسبوع 5 | O6: ="أسبوع 6" -> أسبوع 6
A7: 1 | B7: تحديد ارتفاعات فتحات الأبواب الداخلية | C7: تعديلات معمارية | D7: المصمم الداخلي | E7: =$B$2+0 -> 46272 | F7: =$B$2+3 -> 46275 | G7: =IF(AND(ISNUMBER(E7),ISNUMBER(F7)),F7-E7+1,"") -> 4 | H7: 0 | I7: تم
A8: 2 | B8: تعديل صبة الدرج للتبليط | C8: تعديلات معمارية | D8: مقاول التنفيذ | E8: =$B$2+0 -> 46272 | F8: =$B$2+6 -> 46278 | G8: =IF(AND(ISNUMBER(E8),ISNUMBER(F8)),F8-E8+1,"") -> 7 | H8: 0 | I8: قيد التنفيذ
A9: 3 | B9: تعديل فتحة باب الدرج | C9: تعديلات معمارية | D9: مقاول التنفيذ | E9: =$B$2+2 -> 46274 | F9: =$B$2+6 -> 46278 | G9: =IF(AND(ISNUMBER(E9),ISNUMBER(F9)),F9-E9+1,"") -> 5 | H9: 0 | I9: لم يبدأ
A10: 4 | B10: صب الدرج الخلفى لباب الدرج | C10: تعديلات معمارية | D10: مقاول التنفيذ | E10: =$B$2+7 -> 46279 | F10: =$B$2+11 -> 46283 | G10: =IF(AND(ISNUMBER(E10),ISNUMBER(F10)),F10-E10+1,"") -> 5 | H10: 0 | I10: لم يبدأ
A11: 5 | B11: تقفيل الرصيف و صب الدرجات الخارجية و الانترلوك | C11: تعديلات معمارية | D11: مقاول التنفيذ | E11: =$B$2+7 -> 46279 | F11: =$B$2+20 -> 46292 | G11: =IF(AND(ISNUMBER(E11),ISNUMBER(F11)),F11-E11+1,"") -> 14 | H11: 0 | I11: لم يبدأ
A12: 6 | B12: صب درجات المداخل فى الاحواش | C12: تعديلات معمارية | D12: مقاول التنفيذ | E12: =$B$2+7 -> 46279 | F12: =$B$2+17 -> 46289 | G12: =IF(AND(ISNUMBER(E12),ISNUMBER(F12)),F12-E12+1,"") -> 11 | H12: 0 | I12: لم يبدأ
A13: 7 | B13: إنهاء تمديد سباكة الأحواض الخارجية بعد العزل | C13: السباكة | D13: مهندس الموقع | E13: =$B$2+0 -> 46272 | F13: =$B$2+13 -> 46285 | G13: =IF(AND(ISNUMBER(E13),ISNUMBER(F13)),F13-E13+1,"") -> 14 | H13: 0 | I13: قيد التنفيذ
A14: 8 | B14: تمديد سباكة الحمامات | C14: السباكة | D14: مهندس الموقع | E14: =$B$2+0 -> 46272 | F14: =$B$2+20 -> 46292 | G14: =IF(AND(ISNUMBER(E14),ISNUMBER(F14)),F14-E14+1,"") -> 21 | H14: 0 | I14: قيد التنفيذ
A15: 9 | B15: توصيل الكهرباء من العمومى | C15: الكهرباء | D15: مهندس الموقع | E15: =$B$2+0 -> 46272 | F15: =$B$2+13 -> 46285 | G15: =IF(AND(ISNUMBER(E15),ISNUMBER(F15)),F15-E15+1,"") -> 14 | H15: 0 | I15: قيد التنفيذ
A16: 10 | B16: توريد و تركيب هود شفط القبو | C16: تمديدات الشفط | D16: مصطفى | E16: =$B$2+7 -> 46279 | F16: =$B$2+20 -> 46292 | G16: =IF(AND(ISNUMBER(E16),ISNUMBER(F16)),F16-E16+1,"") -> 14 | H16: 0 | I16: تم
A17: 11 | B17: مراوح الشفط للحمامات و المطبخ العلوى | C17: تمديدات الشفط | D17: مصطفى | E17: =$B$2+14 -> 46286 | F17: =$B$2+20 -> 46292 | G17: =IF(AND(ISNUMBER(E17),ISNUMBER(F17)),F17-E17+1,"") -> 7 | H17: 0 | I17: لم يبدأ
A18: 12 | B18: تعديل دولاب العبايات ليتوافق مع ارتفاع الأبواب | C18: الجبس | D18: مقاول جبس | E18: =$B$2+7 -> 46279 | F18: =$B$2+13 -> 46285 | G18: =IF(AND(ISNUMBER(E18),ISNUMBER(F18)),F18-E18+1,"") -> 7 | H18: 0 | I18: لم يبدأ
A19: 13 | B19: استكمال أعمال البانوهات فى باقى الفيلا | C19: الجبس | D19: مقاول جبس | E19: =$B$2+7 -> 46279 | F19: =$B$2+27 -> 46299 | G19: =IF(AND(ISNUMBER(E19),ISNUMBER(F19)),F19-E19+1,"") -> 21 | H19: 0 | I19: لم يبدأ
A20: 14 | B20: جبس بورد الحمامات | C20: الجبس | D20: مقاول جبس | E20: =$B$2+14 -> 46286 | F20: =$B$2+27 -> 46299 | G20: =IF(AND(ISNUMBER(E20),ISNUMBER(F20)),F20-E20+1,"") -> 14 | H20: 0 | I20: لم يبدأ
A21: 15 | B21: جبس بورد صالة الأرضى بالتنسيق مع النجار | C21: الجبس | D21: مقاول جبس | E21: =$B$2+21 -> 46293 | F21: =$B$2+27 -> 46299 | G21: =IF(AND(ISNUMBER(E21),ISNUMBER(F21)),F21-E21+1,"") -> 7 | H21: 0 | I21: لم يبدأ
A22: 16 | B22: ديكور تلفزيون غرفة النوم (يحتاج حديد تدعيم) | C22: الجبس | D22: مقاول جبس | E22: =$B$2+14 -> 46286 | F22: =$B$2+20 -> 46292 | G22: =IF(AND(ISNUMBER(E22),ISNUMBER(F22)),F22-E22+1,"") -> 7 | H22: 0 | I22: لم يبدأ
A23: 17 | B23: تدعيم ديكور التلفزيون غرفة النوم | C23: الحدادة | D23: مصطفى | E23: =$B$2+14 -> 46286 | F23: =$B$2+17 -> 46289 | G23: =IF(AND(ISNUMBER(E23),ISNUMBER(F23)),F23-E23+1,"") -> 4 | H23: 0 | I23: لم يبدأ
A24: 18 | B24: تدعيم الباب السحاب لغرفة النوم بالتنسيق مع النجار | C24: الحدادة | D24: مصطفى | E24: =$B$2+14 -> 46286 | F24: =$B$2+20 -> 46292 | G24: =IF(AND(ISNUMBER(E24),ISNUMBER(F24)),F24-E24+1,"") -> 7 | H24: 0 | I24: لم يبدأ
A25: 19 | B25: تنفيذ درابزين الدرج و البلكونات و البهو الداخلى | C25: الحدادة | D25: مصطفى | E25: =$B$2+21 -> 46293 | F25: =$B$2+41 -> 46313 | G25: =IF(AND(ISNUMBER(E25),ISNUMBER(F25)),F25-E25+1,"") -> 21 | H25: 0 | I25: لم يبدأ
A26: 20 | B26: اعتماد عينة الحمام المتبلط كامل | C26: التبليط | D26: مهندس الموقع | E26: =$B$2+0 -> 46272 | F26: =$B$2+6 -> 46278 | G26: =IF(AND(ISNUMBER(E26),ISNUMBER(F26)),F26-E26+1,"") -> 7 | H26: 0 | I26: قيد التنفيذ
A27: 21 | B27: توريد بلاط أرضيات الحمامات (متأخر بالجمارك) | C27: التبليط | D27: مهندس الموقع | E27: =$B$2+0 -> 46272 | F27: =$B$2+13 -> 46285 | G27: =IF(AND(ISNUMBER(E27),ISNUMBER(F27)),F27-E27+1,"") -> 14 | H27: 0 | I27: قيد التنفيذ
A28: 22 | B28: توريد بلاط زيادة للسطح لجدار حوض الزرع | C28: التبليط | D28: مهندس الموقع | E28: =$B$2+7 -> 46279 | F28: =$B$2+13 -> 46285 | G28: =IF(AND(ISNUMBER(E28),ISNUMBER(F28)),F28-E28+1,"") -> 7 | H28: 0 | I28: لم يبدأ
A29: 23 | B29: تبليط أرضية القبو | C29: التبليط | D29: مقاول التبليط | E29: =$B$2+14 -> 46286 | F29: =$B$2+27 -> 46299 | G29: =IF(AND(ISNUMBER(E29),ISNUMBER(F29)),F29-E29+1,"") -> 14 | H29: 0 | I29: لم يبدأ
A30: 24 | B30: تبليط الأحواش الخارجية (بعد العزل و اختباره) | C30: التبليط | D30: مقاول التبليط | E30: =$B$2+14 -> 46286 | F30: =$B$2+34 -> 46306 | G30: =IF(AND(ISNUMBER(E30),ISNUMBER(F30)),F30-E30+1,"") -> 21 | H30: 0 | I30: لم يبدأ
A31: 25 | B31: تبليط الدرج الخارجى رخام | C31: التبليط | D31: A MARBLE | E31: =$B$2+21 -> 46293 | F31: =$B$2+34 -> 46306 | G31: =IF(AND(ISNUMBER(E31),ISNUMBER(F31)),F31-E31+1,"") -> 14 | H31: 0 | I31: لم يبدأ
A32: 26 | B32: تبليط بلكونات الارتداد | C32: التبليط | D32: مقاول التبليط | E32: =$B$2+21 -> 46293 | F32: =$B$2+34 -> 46306 | G32: =IF(AND(ISNUMBER(E32),ISNUMBER(F32)),F32-E32+1,"") -> 14 | H32: 0 | I32: لم يبدأ
A33: 27 | B33: تركيب رخام أرضيات الدور الأرضى | C33: التبليط | D33: A MARBLE | E33: =$B$2+21 -> 46293 | F33: =$B$2+41 -> 46313 | G33: =IF(AND(ISNUMBER(E33),ISNUMBER(F33)),F33-E33+1,"") -> 21 | H33: 0 | I33: لم يبدأ
A34: 28 | B34: إغلاق عروض الأسعار و تعميد الدرابزين | C34: التعميدات | D34: مصطفى | E34: =$B$2+0 -> 46272 | F34: =$B$2+13 -> 46285 | G34: =IF(AND(ISNUMBER(E34),ISNUMBER(F34)),F34-E34+1,"") -> 14 | H34: 0 | I34: قيد التنفيذ
A35: 29 | B35: اعتماد طريقة تركيب رخام الدرج و النعلة | C35: التعميدات | D35: مهندس التشطيبات | E35: =$B$2+0 -> 46272 | F35: =$B$2+13 -> 46285 | G35: =IF(AND(ISNUMBER(E35),ISNUMBER(F35)),F35-E35+1,"") -> 14 | H35: 0 | I35: قيد التنفيذ
A36: 30 | B36: اعتماد عينة الباركيه و البروفايل للدهان | C36: التعميدات | D36: مصطفى | E36: =$B$2+7 -> 46279 | F36: =$B$2+20 -> 46292 | G36: =IF(AND(ISNUMBER(E36),ISNUMBER(F36)),F36-E36+1,"") -> 14 | H36: 0 | I36: لم يبدأ
A37: 31 | B37: اعتماد مصنع السجاد (الصين) | C37: التعميدات | D37: مصطفى | E37: =$B$2+7 -> 46279 | F37: =$B$2+20 -> 46292 | G37: =IF(AND(ISNUMBER(E37),ISNUMBER(F37)),F37-E37+1,"") -> 14 | H37: 0 | I37: لم يبدأ
A38: 32 | B38: استكمال حصر جداول التوريدات الناقصة | C38: التوريدات | D38: مصطفى | E38: =$B$2+0 -> 46272 | F38: =$B$2+20 -> 46292 | G38: =IF(AND(ISNUMBER(E38),ISNUMBER(F38)),F38-E38+1,"") -> 21 | H38: 0 | I38: قيد التنفيذ
A39: 33 | B39: إصدار أوامر التوريد طويلة الأمد (سجاد/إضاءة/ستائر) | C39: التوريدات | D39: مصطفى | E39: =$B$2+14 -> 46286 | F39: =$B$2+41 -> 46313 | G39: =IF(AND(ISNUMBER(E39),ISNUMBER(F39)),F39-E39+1,"") -> 28 | H39: 0 | I39: لم يبدأ
A40: 34 | B40: مخططات تنفيذ الأعمال الخشبية | C40: يونايت اكس | E40: =$B$2+0 -> 46272 | F40: =$B$2+13 -> 46285 | G40: =IF(AND(ISNUMBER(E40),ISNUMBER(F40)),F40-E40+1,"") -> 14 | H40: 0 | I40: قيد التنفيذ
A41: 35 | B41: تصنيع الأبواب و الوحدات الخشبية | C41: يونايت اكس | D41: UNIT X | E41: =$B$2+14 -> 46286 | F41: =$B$2+41 -> 46313 | G41: =IF(AND(ISNUMBER(E41),ISNUMBER(F41)),F41-E41+1,"") -> 28 | H41: 0 | I41: لم يبدأ
...

Sheet ملاحظات
A1: جدول ملاحظات زيارة الموقع 14-7 | F1: ↩ الفهرس
A2: م | B2: الملاحظة | C2: المكان / الموقع | D2: الإجراء | E2: الحالة
A3: 1 | B3: مكان السباكة فى الجدار | C3: حمام الماستر | D3: تعديلات الجدار تتم بعد تفنيش السباكة النهائى | E3: معلق
A4: 2 | B4: حماية العزل | C4: حمام الماستر | D4: تغطية العزل بالصبه يتم بعد انتهاء السباكة | E4: معلق
A5: 3 | B5: صفاية السطح مخفية | C5: السطح | D5: تم ارسال الملاحظة سابقا للمقاول | E5: قيد التنفيذ
A6: 4 | B6: وجود تجميع للاحواض الزراعة كصرف | C6: السطح | D6: مجمعه فى الاسفل بالسقف | E6: منتهى
A7: 5 | B7: تكملة تبليط الاحواض | C7: السطح | E7: قيد التنفيذ
A8: 6 | B8: اعادة صبه الدرج | C8: الدرج | E8: قيد التنفيذ
A9: 7 | B9: تركيب الالمونيم جهه الدرج لاختبار التكييف | C9: الدرج | D9: لا يمكن تركيبه الا بعد تركيب رخام الدرج | E9: معلق
A10: 8 | B10: عزل الالمونيوم و تغطيته و نظافته | D10: تم تغطيته من قبل و سيتم اعادة تغطيته مرة اخرى | E10: قيد التنفيذ
A11: 9 | B11: حل مشكلة باب الدرج | C11: الدرج | E11: قيد التنفيذ
A12: 10 | B12: تمديد صرف احواض القبو | C12: القبو | D12: تم ارسالها سابقا للمقاول | E12: قيد التنفيذ
A13: 11 | B13: اعتماد ارتفاع لابواب فراغات القبو | C13: القبو | E13: قيد التنفيذ
A14: 12 | B14: صرف المطر لدرج القبو | D14: يوجد صرف اسفل الدرج | E14: قيد التنفيذ
A15: 13 | B15: تعديل فى الحوض بحوش مدخل الضيوف | C15: المدخل | D15: ما هو التعديل ؟ | E15: لم يبدأ
A16: 14 | B16: تركيب اسكاي لايت للقبو | C16: الارتداد | D16: لا يمكن تركيبها قبل العزل و تركيب الهود | E16: معلق
A17: 15 | B17: هود شفط القبو | C17: القبو | D17: جار اعتماد مقاول (يوجد عروض اسعار) | E17: قيد التنفيذ
A18: 16 | B18: تقفيل الاحواض الخارجية مع الرصيف | C18: الخارجى | E18: قيد التنفيذ
A19: 17 | B19: نطافة و ترتيب الموقع العام | C19: الخارجى | E19: قيد التنفيذ
A20: ملاحظات عامة

Sheet السجاد - الصين
A1: جدول رقم 3 - السجاد و الموكيت | L1: ↩ الفهرس
A2: م | B2: المواصفات | C2: الكمية | D2: الموقع | E2: الابعاد | F2: الخامات | G2: المورد | H2: سعر الوحدة | I2: الاجمالى | J2: الصورة التوضيحية | K2: ملاحظات
A3: 1 | B3: سجاد ارضي لغرفة السينما | C3: 1 | D3: غرفة السينما | E3: 640 X 400 | I3: =H3*C3
A4: 2 | B4: سجاد ارضي للمكتب | C4: 1 | D4: المكتب | E4: 400 X 320 | I4: =H4*C4
A5: 3 | B5: سجاد ارضي سفل طاولة الطعام | C5: 1 | D5: غرفة الطعام القبو | E5: 440 X 280 | I5: =H5*C5 | J5: تحديد الشكل من طرف المصمم
A6: 4 | B6: توريد وتركيب سجاد ايرانى ارضي في مجلس الرجال | C6: 1 | D6: مجلس الرجال | E6: 450 X 645 | I6: =H6*C6
A7: 5 | B7: توريد وتركيب سجاد ايرانى ارضي في مجلس النساء | C7: 1 | D7: مجلس النساء | E7: 450 X 550 | I7: =H7*C7
A8: 6 | B8: سجاد أرضية اسفل طاولات الطعام | C8: 1 | D8: صالة الطعام الرئيسى | E8: 450 X 300 | I8: =H8*C8 | K8: نحتاج الشكل اللي مسعر عليه
A9: 7 | B9: سجاد أرضية في الصالة الرئيسية لون بيج سادة | C9: 1 | D9: الصالة الرئيسية | E9: 450 X 370 | I9: =H9*C9
A10: 8 | B10: سجاد ايرانى ديكور معلق على الجدار | C10: 1 | D10: مجلس الرجال | E10: 185 X 265 | I10: =H10*C10 | K10: نحتاج كاتلوج للاشكال اللي عنده نختار منها
A11: 9 | B11: سجاد ايرانى ديكور معلق على الجدار | C11: 1 | D11: مجلس النساء | E11: 185 X 250 | I11: =H11*C11
A12: 10 | B12: سجاد ارضي في غرفة النوم الرئيسية | C12: 1 | D12: جناح الماستر | E12: 720 X 500 | I12: =H12*C12
A13: 11 | B13: توريد وتركيب سجاد ارضي في منطقة الملابس | C13: 1 | D13: جناح الماستر | E13: 100 X 700 | I13: =H13*C13
A14: 12 | B14: توريد وتركيب سجاد ارضي في منطقة البار | C14: 1 | D14: جناح الماستر | E14: 180*350 | I14: =H14*C14 | K14: تم وضع المقاس نحتاج سعر لها
A15: 13 | B15: توريد وتركيب سجاد ارضي اسفل السرير | C15: 1 | D15: غرفة النوم 4 | E15: 290 X 180 | I15: =H15*C15
A16: 14 | B16: توريد وتركيب سجاد ارضي اسفل السرير | C16: 1 | D16: غرفة النوم 3 | E16: 310 X 235 | I16: =H16*C16
A17: 15 | B17: توريد وتركيب سجاد ارضي اسفل السرير | C17: 1 | D17: غرفة النوم 2 | E17: 315 X 215 | I17: =H17*C17
A18: 16 | B18: توريد وتركيب سجاد ارضي اسفل السرير | C18: 1 | D18: غرفة النوم 1 | E18: 310 X 200 | I18: =H18*C18 | K18: نحتاج تفصيل نفس الشكل
A19: 17 | B19: سجاد ارضي اسفل طاولة الطعام | C19: 1 | D19: غرفة المعيشة | E19: 235 X 340 | I19: =H19*C19
A20: 18 | B20: سجاد ارضي اسفل جلسة غرفة المعيشة | C20: 1 | D20: غرفة المعيشة | E20: 530 X 340 | I20: =H20*C20
A21: 19 | B21: موكيت ارضي بيضاوى الشكل | C21: 1 | D21: غرفة | E21: 200*300 | I21: =H21*C21 | K21: تم وضع المقاس نحتاج سعر لها
A22: الإجمالى | I22: =SUM(I3:I21)
A23: يتم اعادة رفع المقاسات فعلى من الموقع قبل اعتماد العرض الاخير
